2023-08-01 07:06:24,481 INFO    StreamThr :6552 [internal.py:wandb_internal():86] W&B internal server running at pid: 6552, started at: 2023-08-01 07:06:24.479854
2023-08-01 07:06:24,484 DEBUG   HandlerThread:6552 [handler.py:handle_request():144] handle_request: status
2023-08-01 07:06:24,489 INFO    WriterThread:6552 [datastore.py:open_for_write():85] open: D:\text_clustering_paper\my-forks\sccl_fork\wandb\run-20230801_070624-5pmk5w6i\run-5pmk5w6i.wandb
2023-08-01 07:06:24,490 DEBUG   SenderThread:6552 [sender.py:send():369] send: header
2023-08-01 07:06:24,556 DEBUG   SenderThread:6552 [sender.py:send():369] send: run
2023-08-01 07:06:28,226 INFO    SenderThread:6552 [dir_watcher.py:__init__():211] watching files in: D:\text_clustering_paper\my-forks\sccl_fork\wandb\run-20230801_070624-5pmk5w6i\files
2023-08-01 07:06:28,227 INFO    SenderThread:6552 [sender.py:_start_run_threads():1100] run started: 5pmk5w6i with start time 1690860984.47687
2023-08-01 07:06:28,240 DEBUG   SenderThread:6552 [sender.py:send_request():396] send_request: summary_record
2023-08-01 07:06:28,241 INFO    SenderThread:6552 [sender.py:_save_file():1354] saving file wandb-summary.json with policy end
2023-08-01 07:06:28,260 DEBUG   HandlerThread:6552 [handler.py:handle_request():144] handle_request: check_version
2023-08-01 07:06:28,260 DEBUG   SenderThread:6552 [sender.py:send_request():396] send_request: check_version
2023-08-01 07:06:29,242 INFO    Thread-16 :6552 [dir_watcher.py:_on_file_created():272] file/dir created: D:\text_clustering_paper\my-forks\sccl_fork\wandb\run-20230801_070624-5pmk5w6i\files\wandb-summary.json
2023-08-01 07:06:32,826 DEBUG   HandlerThread:6552 [handler.py:handle_request():144] handle_request: status_report
2023-08-01 07:06:33,161 DEBUG   HandlerThread:6552 [handler.py:handle_request():144] handle_request: run_start
2023-08-01 07:06:33,428 DEBUG   HandlerThread:6552 [system_info.py:__init__():31] System info init
2023-08-01 07:06:33,428 DEBUG   HandlerThread:6552 [system_info.py:__init__():46] System info init done
2023-08-01 07:06:33,428 INFO    HandlerThread:6552 [system_monitor.py:start():181] Starting system monitor
2023-08-01 07:06:33,429 INFO    SystemMonitor:6552 [system_monitor.py:_start():145] Starting system asset monitoring threads
2023-08-01 07:06:33,430 INFO    HandlerThread:6552 [system_monitor.py:probe():201] Collecting system info
2023-08-01 07:06:33,434 INFO    SystemMonitor:6552 [interfaces.py:start():190] Started cpu monitoring
2023-08-01 07:06:33,434 INFO    SystemMonitor:6552 [interfaces.py:start():190] Started disk monitoring
2023-08-01 07:06:33,435 INFO    SystemMonitor:6552 [interfaces.py:start():190] Started gpu monitoring
2023-08-01 07:06:33,436 INFO    SystemMonitor:6552 [interfaces.py:start():190] Started memory monitoring
2023-08-01 07:06:33,456 INFO    SystemMonitor:6552 [interfaces.py:start():190] Started network monitoring
2023-08-01 07:06:33,477 DEBUG   HandlerThread:6552 [system_info.py:probe():195] Probing system
2023-08-01 07:06:33,479 DEBUG   HandlerThread:6552 [system_info.py:_probe_git():180] Probing git
2023-08-01 07:06:33,481 ERROR   gpu       :6552 [interfaces.py:monitor():144] Failed to sample metric: Not Supported
2023-08-01 07:06:33,481 ERROR   gpu       :6552 [interfaces.py:monitor():144] Failed to sample metric: Not Supported
2023-08-01 07:06:33,575 DEBUG   HandlerThread:6552 [system_info.py:_probe_git():188] Probing git done
2023-08-01 07:06:33,575 DEBUG   HandlerThread:6552 [system_info.py:probe():240] Probing system done
2023-08-01 07:06:33,575 DEBUG   HandlerThread:6552 [system_monitor.py:probe():210] {'os': 'Windows-10-10.0.19045-SP0', 'python': '3.11.3', 'heartbeatAt': '2023-08-01T03:36:33.477878', 'startedAt': '2023-08-01T03:36:24.449618', 'docker': None, 'cuda': None, 'args': ('--max_iter=300',), 'state': 'running', 'program': 'D:\\text_clustering_paper\\my-forks\\sccl_fork\\main.py', 'codePath': 'main.py', 'git': {'remote': 'https://github.com/MohammadVahidiPro/sccl_fork.git', 'commit': 'e903c9dc7869a210f161005161d8da308b793a86'}, 'email': 'mohammadvahidi.pro@gmail.com', 'root': 'D:/text_clustering_paper/my-forks/sccl_fork', 'host': 'DESKTOP-59KKEO0', 'username': 'Mohammad', 'executable': 'C:\\Users\\98914\\anaconda3\\envs\\clonetop2_sccl\\python.exe', 'cpu_count': 4, 'cpu_count_logical': 8, 'cpu_freq': {'current': 1792.0, 'min': 0.0, 'max': 1992.0}, 'cpu_freq_per_core': [{'current': 1792.0, 'min': 0.0, 'max': 1992.0}], 'disk': {'total': 585.9374961853027, 'used': 43.22572326660156}, 'gpu': 'NVIDIA GeForce MX150', 'gpu_count': 1, 'gpu_devices': [{'name': 'NVIDIA GeForce MX150', 'memory_total': 4294967296}], 'memory': {'total': 15.877574920654297}}
2023-08-01 07:06:33,575 INFO    HandlerThread:6552 [system_monitor.py:probe():211] Finished collecting system info
2023-08-01 07:06:33,575 INFO    HandlerThread:6552 [system_monitor.py:probe():214] Publishing system info
2023-08-01 07:06:33,575 DEBUG   HandlerThread:6552 [system_info.py:_save_pip():51] Saving list of pip packages installed into the current environment
2023-08-01 07:06:33,576 DEBUG   HandlerThread:6552 [system_info.py:_save_pip():67] Saving pip packages done
2023-08-01 07:06:33,577 DEBUG   HandlerThread:6552 [system_info.py:_save_conda():74] Saving list of conda packages installed into the current environment
2023-08-01 07:06:34,291 INFO    Thread-16 :6552 [dir_watcher.py:_on_file_created():272] file/dir created: D:\text_clustering_paper\my-forks\sccl_fork\wandb\run-20230801_070624-5pmk5w6i\files\requirements.txt
2023-08-01 07:06:34,292 INFO    Thread-16 :6552 [dir_watcher.py:_on_file_created():272] file/dir created: D:\text_clustering_paper\my-forks\sccl_fork\wandb\run-20230801_070624-5pmk5w6i\files\conda-environment.yaml
2023-08-01 07:06:35,576 ERROR   gpu       :6552 [interfaces.py:monitor():144] Failed to sample metric: Not Supported
2023-08-01 07:06:35,576 ERROR   gpu       :6552 [interfaces.py:monitor():144] Failed to sample metric: Not Supported
2023-08-01 07:06:37,667 ERROR   gpu       :6552 [interfaces.py:monitor():144] Failed to sample metric: Not Supported
2023-08-01 07:06:37,667 ERROR   gpu       :6552 [interfaces.py:monitor():144] Failed to sample metric: Not Supported
2023-08-01 07:06:39,714 ERROR   gpu       :6552 [interfaces.py:monitor():144] Failed to sample metric: Not Supported
2023-08-01 07:06:39,714 ERROR   gpu       :6552 [interfaces.py:monitor():144] Failed to sample metric: Not Supported
2023-08-01 07:06:41,809 ERROR   gpu       :6552 [interfaces.py:monitor():144] Failed to sample metric: Not Supported
2023-08-01 07:06:41,810 ERROR   gpu       :6552 [interfaces.py:monitor():144] Failed to sample metric: Not Supported
2023-08-01 07:06:43,848 ERROR   gpu       :6552 [interfaces.py:monitor():144] Failed to sample metric: Unknown Error
2023-08-01 07:06:43,848 ERROR   gpu       :6552 [interfaces.py:monitor():144] Failed to sample metric: Unknown Error
2023-08-01 07:06:43,996 ERROR   gpu       :6552 [interfaces.py:monitor():144] Failed to sample metric: Not Supported
2023-08-01 07:06:43,996 ERROR   gpu       :6552 [interfaces.py:monitor():144] Failed to sample metric: Not Supported
2023-08-01 07:06:46,004 ERROR   gpu       :6552 [interfaces.py:monitor():144] Failed to sample metric: Not Supported
2023-08-01 07:06:46,005 ERROR   gpu       :6552 [interfaces.py:monitor():144] Failed to sample metric: Not Supported
2023-08-01 07:06:48,007 ERROR   gpu       :6552 [interfaces.py:monitor():144] Failed to sample metric: Not Supported
2023-08-01 07:06:48,007 ERROR   gpu       :6552 [interfaces.py:monitor():144] Failed to sample metric: Not Supported
2023-08-01 07:06:50,104 ERROR   gpu       :6552 [interfaces.py:monitor():144] Failed to sample metric: Not Supported
2023-08-01 07:06:50,104 ERROR   gpu       :6552 [interfaces.py:monitor():144] Failed to sample metric: Not Supported
2023-08-01 07:06:50,984 DEBUG   HandlerThread:6552 [system_info.py:_save_conda():86] Saving conda packages done
2023-08-01 07:06:50,984 DEBUG   HandlerThread:6552 [system_info.py:_save_code():89] Saving code
2023-08-01 07:06:51,084 DEBUG   HandlerThread:6552 [system_info.py:_save_code():110] Saving code done
2023-08-01 07:06:51,084 DEBUG   HandlerThread:6552 [system_info.py:_save_patches():127] Saving git patches
2023-08-01 07:06:51,394 INFO    Thread-16 :6552 [dir_watcher.py:_on_file_modified():289] file/dir modified: D:\text_clustering_paper\my-forks\sccl_fork\wandb\run-20230801_070624-5pmk5w6i\files\conda-environment.yaml
2023-08-01 07:06:51,395 INFO    Thread-16 :6552 [dir_watcher.py:_on_file_created():272] file/dir created: D:\text_clustering_paper\my-forks\sccl_fork\wandb\run-20230801_070624-5pmk5w6i\files\code\main.py
2023-08-01 07:06:51,396 INFO    Thread-16 :6552 [dir_watcher.py:_on_file_created():272] file/dir created: D:\text_clustering_paper\my-forks\sccl_fork\wandb\run-20230801_070624-5pmk5w6i\files\code
2023-08-01 07:06:52,206 ERROR   gpu       :6552 [interfaces.py:monitor():144] Failed to sample metric: Not Supported
2023-08-01 07:06:52,211 ERROR   gpu       :6552 [interfaces.py:monitor():144] Failed to sample metric: Not Supported
2023-08-01 07:06:54,271 ERROR   gpu       :6552 [interfaces.py:monitor():144] Failed to sample metric: Unknown Error
2023-08-01 07:06:54,272 ERROR   gpu       :6552 [interfaces.py:monitor():144] Failed to sample metric: Unknown Error
2023-08-01 07:06:54,417 ERROR   gpu       :6552 [interfaces.py:monitor():144] Failed to sample metric: Not Supported
2023-08-01 07:06:54,417 ERROR   gpu       :6552 [interfaces.py:monitor():144] Failed to sample metric: Not Supported
2023-08-01 07:06:54,419 INFO    Thread-16 :6552 [dir_watcher.py:_on_file_created():272] file/dir created: D:\text_clustering_paper\my-forks\sccl_fork\wandb\run-20230801_070624-5pmk5w6i\files\diff.patch
2023-08-01 07:06:55,423 INFO    Thread-16 :6552 [dir_watcher.py:_on_file_modified():289] file/dir modified: D:\text_clustering_paper\my-forks\sccl_fork\wandb\run-20230801_070624-5pmk5w6i\files\diff.patch
2023-08-01 07:06:56,420 ERROR   gpu       :6552 [interfaces.py:monitor():144] Failed to sample metric: Not Supported
2023-08-01 07:06:56,421 ERROR   gpu       :6552 [interfaces.py:monitor():144] Failed to sample metric: Not Supported
2023-08-01 07:06:57,441 INFO    Thread-16 :6552 [dir_watcher.py:_on_file_modified():289] file/dir modified: D:\text_clustering_paper\my-forks\sccl_fork\wandb\run-20230801_070624-5pmk5w6i\files\diff.patch
2023-08-01 07:06:57,442 INFO    Thread-16 :6552 [dir_watcher.py:_on_file_created():272] file/dir created: D:\text_clustering_paper\my-forks\sccl_fork\wandb\run-20230801_070624-5pmk5w6i\files\upstream_diff_94cb2df46703d3266d43f731c56849ac84c15bc0.patch
2023-08-01 07:06:58,500 INFO    Thread-16 :6552 [dir_watcher.py:_on_file_modified():289] file/dir modified: D:\text_clustering_paper\my-forks\sccl_fork\wandb\run-20230801_070624-5pmk5w6i\files\upstream_diff_94cb2df46703d3266d43f731c56849ac84c15bc0.patch
2023-08-01 07:06:58,500 ERROR   gpu       :6552 [interfaces.py:monitor():144] Failed to sample metric: Not Supported
2023-08-01 07:06:58,501 ERROR   gpu       :6552 [interfaces.py:monitor():144] Failed to sample metric: Not Supported
2023-08-01 07:06:59,511 INFO    Thread-16 :6552 [dir_watcher.py:_on_file_modified():289] file/dir modified: D:\text_clustering_paper\my-forks\sccl_fork\wandb\run-20230801_070624-5pmk5w6i\files\upstream_diff_94cb2df46703d3266d43f731c56849ac84c15bc0.patch
2023-08-01 07:07:00,547 ERROR   gpu       :6552 [interfaces.py:monitor():144] Failed to sample metric: Not Supported
2023-08-01 07:07:00,547 ERROR   gpu       :6552 [interfaces.py:monitor():144] Failed to sample metric: Not Supported
2023-08-01 07:07:00,635 INFO    Thread-16 :6552 [dir_watcher.py:_on_file_modified():289] file/dir modified: D:\text_clustering_paper\my-forks\sccl_fork\wandb\run-20230801_070624-5pmk5w6i\files\upstream_diff_94cb2df46703d3266d43f731c56849ac84c15bc0.patch
2023-08-01 07:07:01,652 INFO    Thread-16 :6552 [dir_watcher.py:_on_file_modified():289] file/dir modified: D:\text_clustering_paper\my-forks\sccl_fork\wandb\run-20230801_070624-5pmk5w6i\files\upstream_diff_94cb2df46703d3266d43f731c56849ac84c15bc0.patch
2023-08-01 07:07:01,820 ERROR   HandlerThread:6552 [system_info.py:_save_patches():168] Error generating diff: Command '['git', 'diff', '--submodule=diff', '94cb2df46703d3266d43f731c56849ac84c15bc0']' timed out after 5 seconds
2023-08-01 07:07:01,820 DEBUG   HandlerThread:6552 [system_info.py:_save_patches():169] Saving git patches done
2023-08-01 07:07:01,821 INFO    HandlerThread:6552 [system_monitor.py:probe():216] Finished publishing system info
2023-08-01 07:07:01,907 DEBUG   HandlerThread:6552 [handler.py:handle_request():144] handle_request: status_report
2023-08-01 07:07:01,907 DEBUG   HandlerThread:6552 [handler.py:handle_request():144] handle_request: keepalive
2023-08-01 07:07:01,907 DEBUG   HandlerThread:6552 [handler.py:handle_request():144] handle_request: status_report
2023-08-01 07:07:01,907 DEBUG   HandlerThread:6552 [handler.py:handle_request():144] handle_request: keepalive
2023-08-01 07:07:01,907 DEBUG   HandlerThread:6552 [handler.py:handle_request():144] handle_request: status_report
2023-08-01 07:07:01,907 DEBUG   HandlerThread:6552 [handler.py:handle_request():144] handle_request: keepalive
2023-08-01 07:07:01,907 DEBUG   HandlerThread:6552 [handler.py:handle_request():144] handle_request: status_report
2023-08-01 07:07:01,907 DEBUG   HandlerThread:6552 [handler.py:handle_request():144] handle_request: keepalive
2023-08-01 07:07:01,907 DEBUG   HandlerThread:6552 [handler.py:handle_request():144] handle_request: status_report
2023-08-01 07:07:01,907 DEBUG   HandlerThread:6552 [handler.py:handle_request():144] handle_request: keepalive
2023-08-01 07:07:01,908 DEBUG   SenderThread:6552 [sender.py:send():369] send: files
2023-08-01 07:07:01,908 INFO    SenderThread:6552 [sender.py:_save_file():1354] saving file wandb-metadata.json with policy now
2023-08-01 07:07:01,909 INFO    SenderThread:6552 [sender.py:_save_file():1354] saving file code\main.py with policy now
2023-08-01 07:07:01,910 INFO    SenderThread:6552 [sender.py:_save_file():1354] saving file diff.patch with policy now
2023-08-01 07:07:01,931 DEBUG   HandlerThread:6552 [handler.py:handle_request():144] handle_request: stop_status
2023-08-01 07:07:01,932 DEBUG   SenderThread:6552 [sender.py:send_request():396] send_request: stop_status
2023-08-01 07:07:02,604 ERROR   gpu       :6552 [interfaces.py:monitor():144] Failed to sample metric: Not Supported
2023-08-01 07:07:02,607 ERROR   gpu       :6552 [interfaces.py:monitor():144] Failed to sample metric: Not Supported
2023-08-01 07:07:02,661 INFO    Thread-16 :6552 [dir_watcher.py:_on_file_created():272] file/dir created: D:\text_clustering_paper\my-forks\sccl_fork\wandb\run-20230801_070624-5pmk5w6i\files\wandb-metadata.json
2023-08-01 07:07:04,331 DEBUG   SenderThread:6552 [sender.py:send():369] send: telemetry
2023-08-01 07:07:04,332 DEBUG   HandlerThread:6552 [handler.py:handle_request():144] handle_request: status_report
2023-08-01 07:07:04,332 DEBUG   SenderThread:6552 [sender.py:send():369] send: telemetry
2023-08-01 07:07:04,335 DEBUG   SenderThread:6552 [sender.py:send():369] send: run
2023-08-01 07:07:04,752 INFO    Thread-16 :6552 [dir_watcher.py:_on_file_modified():289] file/dir modified: D:\text_clustering_paper\my-forks\sccl_fork\wandb\run-20230801_070624-5pmk5w6i\files\config.yaml
2023-08-01 07:07:04,799 ERROR   gpu       :6552 [interfaces.py:aggregate():161] Failed to serialize metric: division by zero
2023-08-01 07:07:04,800 ERROR   gpu       :6552 [interfaces.py:monitor():144] Failed to sample metric: Not Supported
2023-08-01 07:07:04,801 ERROR   gpu       :6552 [interfaces.py:monitor():144] Failed to sample metric: Not Supported
2023-08-01 07:07:05,806 ERROR   wandb-upload_0:6552 [internal_api.py:upload_file():2287] upload_file exception https://storage.googleapis.com/wandb-production.appspot.com/mohammadvahidi-pro/sccl-2021/5pmk5w6i/wandb-metadata.json?Expires=1690947423&GoogleAccessId=gorilla-files-url-signer-man%40wandb-production.iam.gserviceaccount.com&Signature=AGzj6DgkBwgyCDWfqAXcULe6W8u7B8e09JMkAhbU3xgD0cSYwG4oMEmvZqYRWnJyGFKZZXCOng9I3I338DEUJTYHwBjSXWADsiGi9BUl%2FoaTHpz6NS8%2FFmsoz9jIdFCBbHjFE6TCh5vX8ggMCSmPauDgZXEqhniDLBSMaGus5ALZlj2zkwLFCAsH4u1zvg9GueogXd%2BNy0YrpDq7QPjZE8kBow8pSb%2FTPVaO9gLOvqJxnzcKhrTErKQA1FSwgVoDEf%2B%2F0GYHS8UPisns15PhIii44vWi4a7pOmrqkPguRaNQeSVfoAYcTY5KsnktxUnILLWVqrSifrvu0Mfg1t8E8A%3D%3D: 403 Client Error: Forbidden for url: https://storage.googleapis.com/wandb-production.appspot.com/mohammadvahidi-pro/sccl-2021/5pmk5w6i/wandb-metadata.json?Expires=1690947423&GoogleAccessId=gorilla-files-url-signer-man%40wandb-production.iam.gserviceaccount.com&Signature=AGzj6DgkBwgyCDWfqAXcULe6W8u7B8e09JMkAhbU3xgD0cSYwG4oMEmvZqYRWnJyGFKZZXCOng9I3I338DEUJTYHwBjSXWADsiGi9BUl%2FoaTHpz6NS8%2FFmsoz9jIdFCBbHjFE6TCh5vX8ggMCSmPauDgZXEqhniDLBSMaGus5ALZlj2zkwLFCAsH4u1zvg9GueogXd%2BNy0YrpDq7QPjZE8kBow8pSb%2FTPVaO9gLOvqJxnzcKhrTErKQA1FSwgVoDEf%2B%2F0GYHS8UPisns15PhIii44vWi4a7pOmrqkPguRaNQeSVfoAYcTY5KsnktxUnILLWVqrSifrvu0Mfg1t8E8A%3D%3D
2023-08-01 07:07:05,806 ERROR   wandb-upload_0:6552 [internal_api.py:upload_file():2289] upload_file request headers: {'User-Agent': 'python-requests/2.29.0', 'Accept-Encoding': 'gzip, deflate, br', 'Accept': '*/*', 'Connection': 'keep-alive', 'Content-Length': '1435'}
2023-08-01 07:07:05,806 ERROR   wandb-upload_0:6552 [internal_api.py:upload_file():2291] upload_file response body: b"<?xml version='1.0' encoding='UTF-8'?><Error><Code>AccessDenied</Code><Message>Access denied.</Message><Details>We're sorry, but this service is not available in your location</Details></Error>"
2023-08-01 07:07:06,913 ERROR   gpu       :6552 [interfaces.py:monitor():144] Failed to sample metric: Not Supported
2023-08-01 07:07:06,915 ERROR   gpu       :6552 [interfaces.py:monitor():144] Failed to sample metric: Not Supported
2023-08-01 07:07:07,867 ERROR   wandb-upload_0:6552 [upload_job.py:push():136] Failed to upload file: C:\Users\98914\AppData\Local\Temp\tmprb1k1jouwandb\y9g24qsa-wandb-metadata.json
Traceback (most recent call last):
  File "C:\Users\98914\anaconda3\envs\clonetop2_sccl\Lib\site-packages\wandb\apis\normalize.py", line 41, in wrapper
    return func(*args, **kwargs)
           ^^^^^^^^^^^^^^^^^^^^^
  File "C:\Users\98914\anaconda3\envs\clonetop2_sccl\Lib\site-packages\wandb\sdk\lib\retry.py", line 212, in wrapped_fn
    return retrier(*args, **kargs)
           ^^^^^^^^^^^^^^^^^^^^^^^
  File "C:\Users\98914\anaconda3\envs\clonetop2_sccl\Lib\site-packages\wandb\sdk\lib\retry.py", line 131, in __call__
    result = self._call_fn(*args, **kwargs)
             ^^^^^^^^^^^^^^^^^^^^^^^^^^^^^^
  File "C:\Users\98914\anaconda3\envs\clonetop2_sccl\Lib\site-packages\wandb\sdk\internal\internal_api.py", line 2313, in upload_file
    wandb._sentry.reraise(e)
  File "C:\Users\98914\anaconda3\envs\clonetop2_sccl\Lib\site-packages\wandb\analytics\sentry.py", line 146, in reraise
    raise exc.with_traceback(sys.exc_info()[2])
  File "C:\Users\98914\anaconda3\envs\clonetop2_sccl\Lib\site-packages\wandb\sdk\internal\internal_api.py", line 2285, in upload_file
    response.raise_for_status()
  File "C:\Users\98914\anaconda3\envs\clonetop2_sccl\Lib\site-packages\requests\models.py", line 1021, in raise_for_status
    raise HTTPError(http_error_msg, response=self)
requests.exceptions.HTTPError: 403 Client Error: Forbidden for url: https://storage.googleapis.com/wandb-production.appspot.com/mohammadvahidi-pro/sccl-2021/5pmk5w6i/wandb-metadata.json?Expires=1690947423&GoogleAccessId=gorilla-files-url-signer-man%40wandb-production.iam.gserviceaccount.com&Signature=AGzj6DgkBwgyCDWfqAXcULe6W8u7B8e09JMkAhbU3xgD0cSYwG4oMEmvZqYRWnJyGFKZZXCOng9I3I338DEUJTYHwBjSXWADsiGi9BUl%2FoaTHpz6NS8%2FFmsoz9jIdFCBbHjFE6TCh5vX8ggMCSmPauDgZXEqhniDLBSMaGus5ALZlj2zkwLFCAsH4u1zvg9GueogXd%2BNy0YrpDq7QPjZE8kBow8pSb%2FTPVaO9gLOvqJxnzcKhrTErKQA1FSwgVoDEf%2B%2F0GYHS8UPisns15PhIii44vWi4a7pOmrqkPguRaNQeSVfoAYcTY5KsnktxUnILLWVqrSifrvu0Mfg1t8E8A%3D%3D

During handling of the above exception, another exception occurred:

Traceback (most recent call last):
  File "C:\Users\98914\anaconda3\envs\clonetop2_sccl\Lib\site-packages\wandb\filesync\upload_job.py", line 127, in push
    self._api.upload_file_retry(
  File "C:\Users\98914\anaconda3\envs\clonetop2_sccl\Lib\site-packages\wandb\apis\normalize.py", line 51, in wrapper
    raise CommError(message, error)
wandb.errors.CommError: <Response [403]>
2023-08-01 07:07:08,016 INFO    SenderThread:6552 [sender.py:send_run():978] updated run: 5pmk5w6i
2023-08-01 07:07:08,016 DEBUG   SenderThread:6552 [sender.py:send():369] send: telemetry
2023-08-01 07:07:08,016 DEBUG   SenderThread:6552 [sender.py:send():369] send: run
2023-08-01 07:07:09,008 INFO    Thread-16 :6552 [dir_watcher.py:_on_file_modified():289] file/dir modified: D:\text_clustering_paper\my-forks\sccl_fork\wandb\run-20230801_070624-5pmk5w6i\files\config.yaml
2023-08-01 07:07:09,009 ERROR   gpu       :6552 [interfaces.py:monitor():144] Failed to sample metric: Not Supported
2023-08-01 07:07:09,009 ERROR   gpu       :6552 [interfaces.py:monitor():144] Failed to sample metric: Not Supported
2023-08-01 07:07:09,058 ERROR   wandb-upload_1:6552 [internal_api.py:upload_file():2287] upload_file exception https://storage.googleapis.com/wandb-production.appspot.com/mohammadvahidi-pro/sccl-2021/5pmk5w6i/code/main.py?Expires=1690947425&GoogleAccessId=gorilla-files-url-signer-man%40wandb-production.iam.gserviceaccount.com&Signature=B1tFdxYyLFOUyAyoFUOR%2B8aujkbG4lKABpfFxN490Efp%2F%2BRuBJK%2BcgCAJAEM%2FxBeq1V551g%2Balp7TmDiV9nlg8Q8OTbTxlRFLRyc8HVV8Sg8ett7qLxJBZQj1i6YaHIye%2FWJ5rQpBLUbsUB9XJoB5%2FPt2TTz%2BndCN6LrI00o1KDY55A23eJY0nEN5STGhfScJiWAyCqab2s%2FykTkNq%2FnHXqPnraxDgeQQ%2B5dq5JSlqG1tQsUYyuoDoZvVVqyN2pds74lo%2BX9hrUaEe%2FROdUYLOnCeccp%2Bd3DcCv4SC%2FOTURDWaGyLoCNUn9%2BfwLoKpa4pS%2Bja2Yd%2BUWt%2FSxvuIirYA%3D%3D: 403 Client Error: Forbidden for url: https://storage.googleapis.com/wandb-production.appspot.com/mohammadvahidi-pro/sccl-2021/5pmk5w6i/code/main.py?Expires=1690947425&GoogleAccessId=gorilla-files-url-signer-man%40wandb-production.iam.gserviceaccount.com&Signature=B1tFdxYyLFOUyAyoFUOR%2B8aujkbG4lKABpfFxN490Efp%2F%2BRuBJK%2BcgCAJAEM%2FxBeq1V551g%2Balp7TmDiV9nlg8Q8OTbTxlRFLRyc8HVV8Sg8ett7qLxJBZQj1i6YaHIye%2FWJ5rQpBLUbsUB9XJoB5%2FPt2TTz%2BndCN6LrI00o1KDY55A23eJY0nEN5STGhfScJiWAyCqab2s%2FykTkNq%2FnHXqPnraxDgeQQ%2B5dq5JSlqG1tQsUYyuoDoZvVVqyN2pds74lo%2BX9hrUaEe%2FROdUYLOnCeccp%2Bd3DcCv4SC%2FOTURDWaGyLoCNUn9%2BfwLoKpa4pS%2Bja2Yd%2BUWt%2FSxvuIirYA%3D%3D
2023-08-01 07:07:09,058 ERROR   wandb-upload_1:6552 [internal_api.py:upload_file():2289] upload_file request headers: {'User-Agent': 'python-requests/2.29.0', 'Accept-Encoding': 'gzip, deflate, br', 'Accept': '*/*', 'Connection': 'keep-alive', 'Content-Length': '8366'}
2023-08-01 07:07:09,059 ERROR   wandb-upload_1:6552 [internal_api.py:upload_file():2291] upload_file response body: b"<?xml version='1.0' encoding='UTF-8'?><Error><Code>AccessDenied</Code><Message>Access denied.</Message><Details>We're sorry, but this service is not available in your location</Details></Error>"
2023-08-01 07:07:09,109 INFO    SenderThread:6552 [sender.py:send_run():978] updated run: 5pmk5w6i
2023-08-01 07:07:10,020 ERROR   Thread-15 (_thread_body):6552 [step_upload.py:_handle_event():200] Failed to upload file: C:\Users\98914\AppData\Local\Temp\tmprb1k1jouwandb\y9g24qsa-wandb-metadata.json
Traceback (most recent call last):
  File "C:\Users\98914\anaconda3\envs\clonetop2_sccl\Lib\site-packages\wandb\apis\normalize.py", line 41, in wrapper
    return func(*args, **kwargs)
           ^^^^^^^^^^^^^^^^^^^^^
  File "C:\Users\98914\anaconda3\envs\clonetop2_sccl\Lib\site-packages\wandb\sdk\lib\retry.py", line 212, in wrapped_fn
    return retrier(*args, **kargs)
           ^^^^^^^^^^^^^^^^^^^^^^^
  File "C:\Users\98914\anaconda3\envs\clonetop2_sccl\Lib\site-packages\wandb\sdk\lib\retry.py", line 131, in __call__
    result = self._call_fn(*args, **kwargs)
             ^^^^^^^^^^^^^^^^^^^^^^^^^^^^^^
  File "C:\Users\98914\anaconda3\envs\clonetop2_sccl\Lib\site-packages\wandb\sdk\internal\internal_api.py", line 2313, in upload_file
    wandb._sentry.reraise(e)
  File "C:\Users\98914\anaconda3\envs\clonetop2_sccl\Lib\site-packages\wandb\analytics\sentry.py", line 146, in reraise
    raise exc.with_traceback(sys.exc_info()[2])
  File "C:\Users\98914\anaconda3\envs\clonetop2_sccl\Lib\site-packages\wandb\sdk\internal\internal_api.py", line 2285, in upload_file
    response.raise_for_status()
  File "C:\Users\98914\anaconda3\envs\clonetop2_sccl\Lib\site-packages\requests\models.py", line 1021, in raise_for_status
    raise HTTPError(http_error_msg, response=self)
requests.exceptions.HTTPError: 403 Client Error: Forbidden for url: https://storage.googleapis.com/wandb-production.appspot.com/mohammadvahidi-pro/sccl-2021/5pmk5w6i/wandb-metadata.json?Expires=1690947423&GoogleAccessId=gorilla-files-url-signer-man%40wandb-production.iam.gserviceaccount.com&Signature=AGzj6DgkBwgyCDWfqAXcULe6W8u7B8e09JMkAhbU3xgD0cSYwG4oMEmvZqYRWnJyGFKZZXCOng9I3I338DEUJTYHwBjSXWADsiGi9BUl%2FoaTHpz6NS8%2FFmsoz9jIdFCBbHjFE6TCh5vX8ggMCSmPauDgZXEqhniDLBSMaGus5ALZlj2zkwLFCAsH4u1zvg9GueogXd%2BNy0YrpDq7QPjZE8kBow8pSb%2FTPVaO9gLOvqJxnzcKhrTErKQA1FSwgVoDEf%2B%2F0GYHS8UPisns15PhIii44vWi4a7pOmrqkPguRaNQeSVfoAYcTY5KsnktxUnILLWVqrSifrvu0Mfg1t8E8A%3D%3D

During handling of the above exception, another exception occurred:

Traceback (most recent call last):
  File "C:\Users\98914\anaconda3\envs\clonetop2_sccl\Lib\concurrent\futures\thread.py", line 58, in run
    result = self.fn(*self.args, **self.kwargs)
             ^^^^^^^^^^^^^^^^^^^^^^^^^^^^^^^^^^
  File "C:\Users\98914\anaconda3\envs\clonetop2_sccl\Lib\site-packages\wandb\filesync\step_upload.py", line 288, in run_and_notify
    self._do_upload_sync(event)
  File "C:\Users\98914\anaconda3\envs\clonetop2_sccl\Lib\site-packages\wandb\filesync\step_upload.py", line 330, in _do_upload_sync
    job.run()
  File "C:\Users\98914\anaconda3\envs\clonetop2_sccl\Lib\site-packages\wandb\filesync\upload_job.py", line 57, in run
    self.push()
  File "C:\Users\98914\anaconda3\envs\clonetop2_sccl\Lib\site-packages\wandb\filesync\upload_job.py", line 127, in push
    self._api.upload_file_retry(
  File "C:\Users\98914\anaconda3\envs\clonetop2_sccl\Lib\site-packages\wandb\apis\normalize.py", line 51, in wrapper
    raise CommError(message, error)
wandb.errors.CommError: <Response [403]>
2023-08-01 07:07:10,116 DEBUG   HandlerThread:6552 [handler.py:handle_request():144] handle_request: status_report
2023-08-01 07:07:10,171 INFO    Thread-16 :6552 [dir_watcher.py:_on_file_created():272] file/dir created: D:\text_clustering_paper\my-forks\sccl_fork\wandb\run-20230801_070624-5pmk5w6i\files\output.log
2023-08-01 07:07:11,195 ERROR   gpu       :6552 [interfaces.py:monitor():144] Failed to sample metric: Not Supported
2023-08-01 07:07:11,196 ERROR   gpu       :6552 [interfaces.py:monitor():144] Failed to sample metric: Not Supported
2023-08-01 07:07:11,219 INFO    Thread-16 :6552 [dir_watcher.py:_on_file_modified():289] file/dir modified: D:\text_clustering_paper\my-forks\sccl_fork\wandb\run-20230801_070624-5pmk5w6i\files\output.log
2023-08-01 07:07:12,026 ERROR   wandb-upload_1:6552 [upload_job.py:push():136] Failed to upload file: C:\Users\98914\AppData\Local\Temp\tmprb1k1jouwandb\rrv2gxd5-code/main.py
Traceback (most recent call last):
  File "C:\Users\98914\anaconda3\envs\clonetop2_sccl\Lib\site-packages\wandb\apis\normalize.py", line 41, in wrapper
    return func(*args, **kwargs)
           ^^^^^^^^^^^^^^^^^^^^^
  File "C:\Users\98914\anaconda3\envs\clonetop2_sccl\Lib\site-packages\wandb\sdk\lib\retry.py", line 212, in wrapped_fn
    return retrier(*args, **kargs)
           ^^^^^^^^^^^^^^^^^^^^^^^
  File "C:\Users\98914\anaconda3\envs\clonetop2_sccl\Lib\site-packages\wandb\sdk\lib\retry.py", line 131, in __call__
    result = self._call_fn(*args, **kwargs)
             ^^^^^^^^^^^^^^^^^^^^^^^^^^^^^^
  File "C:\Users\98914\anaconda3\envs\clonetop2_sccl\Lib\site-packages\wandb\sdk\internal\internal_api.py", line 2313, in upload_file
    wandb._sentry.reraise(e)
  File "C:\Users\98914\anaconda3\envs\clonetop2_sccl\Lib\site-packages\wandb\analytics\sentry.py", line 146, in reraise
    raise exc.with_traceback(sys.exc_info()[2])
  File "C:\Users\98914\anaconda3\envs\clonetop2_sccl\Lib\site-packages\wandb\sdk\internal\internal_api.py", line 2285, in upload_file
    response.raise_for_status()
  File "C:\Users\98914\anaconda3\envs\clonetop2_sccl\Lib\site-packages\requests\models.py", line 1021, in raise_for_status
    raise HTTPError(http_error_msg, response=self)
requests.exceptions.HTTPError: 403 Client Error: Forbidden for url: https://storage.googleapis.com/wandb-production.appspot.com/mohammadvahidi-pro/sccl-2021/5pmk5w6i/code/main.py?Expires=1690947425&GoogleAccessId=gorilla-files-url-signer-man%40wandb-production.iam.gserviceaccount.com&Signature=B1tFdxYyLFOUyAyoFUOR%2B8aujkbG4lKABpfFxN490Efp%2F%2BRuBJK%2BcgCAJAEM%2FxBeq1V551g%2Balp7TmDiV9nlg8Q8OTbTxlRFLRyc8HVV8Sg8ett7qLxJBZQj1i6YaHIye%2FWJ5rQpBLUbsUB9XJoB5%2FPt2TTz%2BndCN6LrI00o1KDY55A23eJY0nEN5STGhfScJiWAyCqab2s%2FykTkNq%2FnHXqPnraxDgeQQ%2B5dq5JSlqG1tQsUYyuoDoZvVVqyN2pds74lo%2BX9hrUaEe%2FROdUYLOnCeccp%2Bd3DcCv4SC%2FOTURDWaGyLoCNUn9%2BfwLoKpa4pS%2Bja2Yd%2BUWt%2FSxvuIirYA%3D%3D

During handling of the above exception, another exception occurred:

Traceback (most recent call last):
  File "C:\Users\98914\anaconda3\envs\clonetop2_sccl\Lib\site-packages\wandb\filesync\upload_job.py", line 127, in push
    self._api.upload_file_retry(
  File "C:\Users\98914\anaconda3\envs\clonetop2_sccl\Lib\site-packages\wandb\apis\normalize.py", line 51, in wrapper
    raise CommError(message, error)
wandb.errors.CommError: <Response [403]>
2023-08-01 07:07:12,230 INFO    Thread-16 :6552 [dir_watcher.py:_on_file_modified():289] file/dir modified: D:\text_clustering_paper\my-forks\sccl_fork\wandb\run-20230801_070624-5pmk5w6i\files\upstream_diff_94cb2df46703d3266d43f731c56849ac84c15bc0.patch
2023-08-01 07:07:13,342 ERROR   gpu       :6552 [interfaces.py:monitor():144] Failed to sample metric: Not Supported
2023-08-01 07:07:13,345 ERROR   gpu       :6552 [interfaces.py:monitor():144] Failed to sample metric: Not Supported
2023-08-01 07:07:14,076 ERROR   Thread-15 (_thread_body):6552 [step_upload.py:_handle_event():200] Failed to upload file: C:\Users\98914\AppData\Local\Temp\tmprb1k1jouwandb\rrv2gxd5-code/main.py
Traceback (most recent call last):
  File "C:\Users\98914\anaconda3\envs\clonetop2_sccl\Lib\site-packages\wandb\apis\normalize.py", line 41, in wrapper
    return func(*args, **kwargs)
           ^^^^^^^^^^^^^^^^^^^^^
  File "C:\Users\98914\anaconda3\envs\clonetop2_sccl\Lib\site-packages\wandb\sdk\lib\retry.py", line 212, in wrapped_fn
    return retrier(*args, **kargs)
           ^^^^^^^^^^^^^^^^^^^^^^^
  File "C:\Users\98914\anaconda3\envs\clonetop2_sccl\Lib\site-packages\wandb\sdk\lib\retry.py", line 131, in __call__
    result = self._call_fn(*args, **kwargs)
             ^^^^^^^^^^^^^^^^^^^^^^^^^^^^^^
  File "C:\Users\98914\anaconda3\envs\clonetop2_sccl\Lib\site-packages\wandb\sdk\internal\internal_api.py", line 2313, in upload_file
    wandb._sentry.reraise(e)
  File "C:\Users\98914\anaconda3\envs\clonetop2_sccl\Lib\site-packages\wandb\analytics\sentry.py", line 146, in reraise
    raise exc.with_traceback(sys.exc_info()[2])
  File "C:\Users\98914\anaconda3\envs\clonetop2_sccl\Lib\site-packages\wandb\sdk\internal\internal_api.py", line 2285, in upload_file
    response.raise_for_status()
  File "C:\Users\98914\anaconda3\envs\clonetop2_sccl\Lib\site-packages\requests\models.py", line 1021, in raise_for_status
    raise HTTPError(http_error_msg, response=self)
requests.exceptions.HTTPError: 403 Client Error: Forbidden for url: https://storage.googleapis.com/wandb-production.appspot.com/mohammadvahidi-pro/sccl-2021/5pmk5w6i/code/main.py?Expires=1690947425&GoogleAccessId=gorilla-files-url-signer-man%40wandb-production.iam.gserviceaccount.com&Signature=B1tFdxYyLFOUyAyoFUOR%2B8aujkbG4lKABpfFxN490Efp%2F%2BRuBJK%2BcgCAJAEM%2FxBeq1V551g%2Balp7TmDiV9nlg8Q8OTbTxlRFLRyc8HVV8Sg8ett7qLxJBZQj1i6YaHIye%2FWJ5rQpBLUbsUB9XJoB5%2FPt2TTz%2BndCN6LrI00o1KDY55A23eJY0nEN5STGhfScJiWAyCqab2s%2FykTkNq%2FnHXqPnraxDgeQQ%2B5dq5JSlqG1tQsUYyuoDoZvVVqyN2pds74lo%2BX9hrUaEe%2FROdUYLOnCeccp%2Bd3DcCv4SC%2FOTURDWaGyLoCNUn9%2BfwLoKpa4pS%2Bja2Yd%2BUWt%2FSxvuIirYA%3D%3D

During handling of the above exception, another exception occurred:

Traceback (most recent call last):
  File "C:\Users\98914\anaconda3\envs\clonetop2_sccl\Lib\concurrent\futures\thread.py", line 58, in run
    result = self.fn(*self.args, **self.kwargs)
             ^^^^^^^^^^^^^^^^^^^^^^^^^^^^^^^^^^
  File "C:\Users\98914\anaconda3\envs\clonetop2_sccl\Lib\site-packages\wandb\filesync\step_upload.py", line 288, in run_and_notify
    self._do_upload_sync(event)
  File "C:\Users\98914\anaconda3\envs\clonetop2_sccl\Lib\site-packages\wandb\filesync\step_upload.py", line 330, in _do_upload_sync
    job.run()
  File "C:\Users\98914\anaconda3\envs\clonetop2_sccl\Lib\site-packages\wandb\filesync\upload_job.py", line 57, in run
    self.push()
  File "C:\Users\98914\anaconda3\envs\clonetop2_sccl\Lib\site-packages\wandb\filesync\upload_job.py", line 127, in push
    self._api.upload_file_retry(
  File "C:\Users\98914\anaconda3\envs\clonetop2_sccl\Lib\site-packages\wandb\apis\normalize.py", line 51, in wrapper
    raise CommError(message, error)
wandb.errors.CommError: <Response [403]>
2023-08-01 07:07:15,250 DEBUG   HandlerThread:6552 [handler.py:handle_request():144] handle_request: status_report
2023-08-01 07:07:15,441 ERROR   gpu       :6552 [interfaces.py:monitor():144] Failed to sample metric: Not Supported
2023-08-01 07:07:15,441 ERROR   gpu       :6552 [interfaces.py:monitor():144] Failed to sample metric: Not Supported
2023-08-01 07:07:16,946 DEBUG   HandlerThread:6552 [handler.py:handle_request():144] handle_request: stop_status
2023-08-01 07:07:16,947 DEBUG   SenderThread:6552 [sender.py:send_request():396] send_request: stop_status
2023-08-01 07:07:17,555 ERROR   gpu       :6552 [interfaces.py:monitor():144] Failed to sample metric: Not Supported
2023-08-01 07:07:17,556 ERROR   gpu       :6552 [interfaces.py:monitor():144] Failed to sample metric: Not Supported
2023-08-01 07:07:19,653 ERROR   gpu       :6552 [interfaces.py:monitor():144] Failed to sample metric: Not Supported
2023-08-01 07:07:19,653 ERROR   gpu       :6552 [interfaces.py:monitor():144] Failed to sample metric: Not Supported
2023-08-01 07:07:21,041 DEBUG   HandlerThread:6552 [handler.py:handle_request():144] handle_request: status_report
2023-08-01 07:07:21,755 ERROR   gpu       :6552 [interfaces.py:monitor():144] Failed to sample metric: Not Supported
2023-08-01 07:07:21,756 ERROR   gpu       :6552 [interfaces.py:monitor():144] Failed to sample metric: Not Supported
2023-08-01 07:07:23,817 ERROR   gpu       :6552 [interfaces.py:monitor():144] Failed to sample metric: Not Supported
2023-08-01 07:07:23,817 ERROR   gpu       :6552 [interfaces.py:monitor():144] Failed to sample metric: Not Supported
2023-08-01 07:07:25,919 ERROR   gpu       :6552 [interfaces.py:monitor():144] Failed to sample metric: Not Supported
2023-08-01 07:07:25,920 ERROR   gpu       :6552 [interfaces.py:monitor():144] Failed to sample metric: Not Supported
2023-08-01 07:07:26,105 DEBUG   HandlerThread:6552 [handler.py:handle_request():144] handle_request: status_report
2023-08-01 07:07:28,040 ERROR   gpu       :6552 [interfaces.py:monitor():144] Failed to sample metric: Not Supported
2023-08-01 07:07:28,040 ERROR   gpu       :6552 [interfaces.py:monitor():144] Failed to sample metric: Not Supported
2023-08-01 07:07:30,154 ERROR   gpu       :6552 [interfaces.py:monitor():144] Failed to sample metric: Not Supported
2023-08-01 07:07:30,154 ERROR   gpu       :6552 [interfaces.py:monitor():144] Failed to sample metric: Not Supported
2023-08-01 07:07:31,167 DEBUG   HandlerThread:6552 [handler.py:handle_request():144] handle_request: status_report
2023-08-01 07:07:31,958 DEBUG   HandlerThread:6552 [handler.py:handle_request():144] handle_request: stop_status
2023-08-01 07:07:32,286 DEBUG   SenderThread:6552 [sender.py:send_request():396] send_request: stop_status
2023-08-01 07:07:32,290 ERROR   gpu       :6552 [interfaces.py:monitor():144] Failed to sample metric: Not Supported
2023-08-01 07:07:32,292 ERROR   gpu       :6552 [interfaces.py:monitor():144] Failed to sample metric: Not Supported
2023-08-01 07:07:32,301 INFO    Thread-16 :6552 [dir_watcher.py:_on_file_modified():289] file/dir modified: D:\text_clustering_paper\my-forks\sccl_fork\wandb\run-20230801_070624-5pmk5w6i\files\config.yaml
2023-08-01 07:07:33,458 DEBUG   SystemMonitor:6552 [system_monitor.py:_start():159] Starting system metrics aggregation loop
2023-08-01 07:07:33,461 DEBUG   SenderThread:6552 [sender.py:send():369] send: stats
2023-08-01 07:07:34,369 ERROR   gpu       :6552 [interfaces.py:monitor():144] Failed to sample metric: Not Supported
2023-08-01 07:07:34,370 ERROR   gpu       :6552 [interfaces.py:monitor():144] Failed to sample metric: Not Supported
2023-08-01 07:07:36,647 ERROR   gpu       :6552 [interfaces.py:aggregate():161] Failed to serialize metric: division by zero
2023-08-01 07:07:36,650 ERROR   gpu       :6552 [interfaces.py:monitor():144] Failed to sample metric: Not Supported
2023-08-01 07:07:36,650 ERROR   gpu       :6552 [interfaces.py:monitor():144] Failed to sample metric: Not Supported
2023-08-01 07:07:37,546 DEBUG   HandlerThread:6552 [handler.py:handle_request():144] handle_request: status_report
2023-08-01 07:07:38,656 ERROR   gpu       :6552 [interfaces.py:monitor():144] Failed to sample metric: Not Supported
2023-08-01 07:07:38,656 ERROR   gpu       :6552 [interfaces.py:monitor():144] Failed to sample metric: Not Supported
2023-08-01 07:07:40,680 ERROR   gpu       :6552 [interfaces.py:monitor():144] Failed to sample metric: Not Supported
2023-08-01 07:07:40,680 ERROR   gpu       :6552 [interfaces.py:monitor():144] Failed to sample metric: Not Supported
2023-08-01 07:07:42,608 DEBUG   HandlerThread:6552 [handler.py:handle_request():144] handle_request: status_report
2023-08-01 07:07:42,795 ERROR   gpu       :6552 [interfaces.py:monitor():144] Failed to sample metric: Not Supported
2023-08-01 07:07:42,796 ERROR   gpu       :6552 [interfaces.py:monitor():144] Failed to sample metric: Not Supported
2023-08-01 07:07:44,913 ERROR   gpu       :6552 [interfaces.py:monitor():144] Failed to sample metric: Not Supported
2023-08-01 07:07:44,914 ERROR   gpu       :6552 [interfaces.py:monitor():144] Failed to sample metric: Not Supported
2023-08-01 07:07:46,985 DEBUG   HandlerThread:6552 [handler.py:handle_request():144] handle_request: stop_status
2023-08-01 07:07:47,040 DEBUG   SenderThread:6552 [sender.py:send_request():396] send_request: stop_status
2023-08-01 07:07:47,048 ERROR   gpu       :6552 [interfaces.py:monitor():144] Failed to sample metric: Not Supported
2023-08-01 07:07:47,049 ERROR   gpu       :6552 [interfaces.py:monitor():144] Failed to sample metric: Not Supported
2023-08-01 07:07:47,928 DEBUG   HandlerThread:6552 [handler.py:handle_request():144] handle_request: status_report
2023-08-01 07:07:49,146 ERROR   gpu       :6552 [interfaces.py:monitor():144] Failed to sample metric: Not Supported
2023-08-01 07:07:49,147 ERROR   gpu       :6552 [interfaces.py:monitor():144] Failed to sample metric: Not Supported
2023-08-01 07:07:51,239 ERROR   gpu       :6552 [interfaces.py:monitor():144] Failed to sample metric: Not Supported
2023-08-01 07:07:51,239 ERROR   gpu       :6552 [interfaces.py:monitor():144] Failed to sample metric: Not Supported
2023-08-01 07:07:52,977 DEBUG   HandlerThread:6552 [handler.py:handle_request():144] handle_request: status_report
2023-08-01 07:07:53,346 ERROR   gpu       :6552 [interfaces.py:monitor():144] Failed to sample metric: Not Supported
2023-08-01 07:07:53,346 ERROR   gpu       :6552 [interfaces.py:monitor():144] Failed to sample metric: Not Supported
2023-08-01 07:07:55,399 ERROR   gpu       :6552 [interfaces.py:monitor():144] Failed to sample metric: Not Supported
2023-08-01 07:07:55,399 ERROR   gpu       :6552 [interfaces.py:monitor():144] Failed to sample metric: Not Supported
2023-08-01 07:07:55,683 ERROR   wandb-upload_2:6552 [internal_api.py:upload_file():2287] upload_file exception https://storage.googleapis.com/wandb-production.appspot.com/mohammadvahidi-pro/sccl-2021/5pmk5w6i/diff.patch?Expires=1690947426&GoogleAccessId=gorilla-files-url-signer-man%40wandb-production.iam.gserviceaccount.com&Signature=Y7A69%2BYLQ2Q%2BI30O0wpglpWO7SzCjDd%2Bq65P1uA5GHMLG1JF4pIXY71K75gRVHmUXmxEyjkHSzvsEcBh8vrp6%2B78RjNpTqfYj5qR8WTRRGc1VGg3CJ3cIpgqVKTCnrHQKotl1wRKqetCbPgtwGTgZWd%2FpvqIJ6%2FvBgVtSZ%2BYNgzU1GTQqc%2BAVBhcqba181MNl10sVrKAMfLXO%2FhQM7%2FiNAeAoAiP4mm1EPF3efFqPwiPr7v7MiYB6Zz4s96NeR%2BeRgBNukWAJE0BjY20ES9XsasLH%2FYukulqVVzcKL7nhAWA3VEZ%2FJVPJoUUiNPdxL9DQQlhJwlTD7VtoCP3fdnKpQ%3D%3D: 403 Client Error: Forbidden for url: https://storage.googleapis.com/wandb-production.appspot.com/mohammadvahidi-pro/sccl-2021/5pmk5w6i/diff.patch?Expires=1690947426&GoogleAccessId=gorilla-files-url-signer-man%40wandb-production.iam.gserviceaccount.com&Signature=Y7A69%2BYLQ2Q%2BI30O0wpglpWO7SzCjDd%2Bq65P1uA5GHMLG1JF4pIXY71K75gRVHmUXmxEyjkHSzvsEcBh8vrp6%2B78RjNpTqfYj5qR8WTRRGc1VGg3CJ3cIpgqVKTCnrHQKotl1wRKqetCbPgtwGTgZWd%2FpvqIJ6%2FvBgVtSZ%2BYNgzU1GTQqc%2BAVBhcqba181MNl10sVrKAMfLXO%2FhQM7%2FiNAeAoAiP4mm1EPF3efFqPwiPr7v7MiYB6Zz4s96NeR%2BeRgBNukWAJE0BjY20ES9XsasLH%2FYukulqVVzcKL7nhAWA3VEZ%2FJVPJoUUiNPdxL9DQQlhJwlTD7VtoCP3fdnKpQ%3D%3D
2023-08-01 07:07:55,683 ERROR   wandb-upload_2:6552 [internal_api.py:upload_file():2289] upload_file request headers: {'User-Agent': 'python-requests/2.29.0', 'Accept-Encoding': 'gzip, deflate, br', 'Accept': '*/*', 'Connection': 'keep-alive', 'Content-Length': '1228543'}
2023-08-01 07:07:55,683 ERROR   wandb-upload_2:6552 [internal_api.py:upload_file():2291] upload_file response body: b"<?xml version='1.0' encoding='UTF-8'?><Error><Code>AccessDenied</Code><Message>Access denied.</Message><Details>We're sorry, but this service is not available in your location</Details></Error>"
2023-08-01 07:07:57,518 ERROR   gpu       :6552 [interfaces.py:monitor():144] Failed to sample metric: Not Supported
2023-08-01 07:07:57,518 ERROR   gpu       :6552 [interfaces.py:monitor():144] Failed to sample metric: Not Supported
2023-08-01 07:07:57,717 ERROR   wandb-upload_2:6552 [upload_job.py:push():136] Failed to upload file: C:\Users\98914\AppData\Local\Temp\tmprb1k1jouwandb\s8uhe7ga-diff.patch
Traceback (most recent call last):
  File "C:\Users\98914\anaconda3\envs\clonetop2_sccl\Lib\site-packages\wandb\apis\normalize.py", line 41, in wrapper
    return func(*args, **kwargs)
           ^^^^^^^^^^^^^^^^^^^^^
  File "C:\Users\98914\anaconda3\envs\clonetop2_sccl\Lib\site-packages\wandb\sdk\lib\retry.py", line 212, in wrapped_fn
    return retrier(*args, **kargs)
           ^^^^^^^^^^^^^^^^^^^^^^^
  File "C:\Users\98914\anaconda3\envs\clonetop2_sccl\Lib\site-packages\wandb\sdk\lib\retry.py", line 131, in __call__
    result = self._call_fn(*args, **kwargs)
             ^^^^^^^^^^^^^^^^^^^^^^^^^^^^^^
  File "C:\Users\98914\anaconda3\envs\clonetop2_sccl\Lib\site-packages\wandb\sdk\internal\internal_api.py", line 2313, in upload_file
    wandb._sentry.reraise(e)
  File "C:\Users\98914\anaconda3\envs\clonetop2_sccl\Lib\site-packages\wandb\analytics\sentry.py", line 146, in reraise
    raise exc.with_traceback(sys.exc_info()[2])
  File "C:\Users\98914\anaconda3\envs\clonetop2_sccl\Lib\site-packages\wandb\sdk\internal\internal_api.py", line 2285, in upload_file
    response.raise_for_status()
  File "C:\Users\98914\anaconda3\envs\clonetop2_sccl\Lib\site-packages\requests\models.py", line 1021, in raise_for_status
    raise HTTPError(http_error_msg, response=self)
requests.exceptions.HTTPError: 403 Client Error: Forbidden for url: https://storage.googleapis.com/wandb-production.appspot.com/mohammadvahidi-pro/sccl-2021/5pmk5w6i/diff.patch?Expires=1690947426&GoogleAccessId=gorilla-files-url-signer-man%40wandb-production.iam.gserviceaccount.com&Signature=Y7A69%2BYLQ2Q%2BI30O0wpglpWO7SzCjDd%2Bq65P1uA5GHMLG1JF4pIXY71K75gRVHmUXmxEyjkHSzvsEcBh8vrp6%2B78RjNpTqfYj5qR8WTRRGc1VGg3CJ3cIpgqVKTCnrHQKotl1wRKqetCbPgtwGTgZWd%2FpvqIJ6%2FvBgVtSZ%2BYNgzU1GTQqc%2BAVBhcqba181MNl10sVrKAMfLXO%2FhQM7%2FiNAeAoAiP4mm1EPF3efFqPwiPr7v7MiYB6Zz4s96NeR%2BeRgBNukWAJE0BjY20ES9XsasLH%2FYukulqVVzcKL7nhAWA3VEZ%2FJVPJoUUiNPdxL9DQQlhJwlTD7VtoCP3fdnKpQ%3D%3D

During handling of the above exception, another exception occurred:

Traceback (most recent call last):
  File "C:\Users\98914\anaconda3\envs\clonetop2_sccl\Lib\site-packages\wandb\filesync\upload_job.py", line 127, in push
    self._api.upload_file_retry(
  File "C:\Users\98914\anaconda3\envs\clonetop2_sccl\Lib\site-packages\wandb\apis\normalize.py", line 51, in wrapper
    raise CommError(message, error)
wandb.errors.CommError: <Response [403]>
2023-08-01 07:07:58,046 DEBUG   HandlerThread:6552 [handler.py:handle_request():144] handle_request: status_report
2023-08-01 07:07:59,634 ERROR   gpu       :6552 [interfaces.py:monitor():144] Failed to sample metric: Not Supported
2023-08-01 07:07:59,635 ERROR   gpu       :6552 [interfaces.py:monitor():144] Failed to sample metric: Not Supported
2023-08-01 07:07:59,746 ERROR   Thread-15 (_thread_body):6552 [step_upload.py:_handle_event():200] Failed to upload file: C:\Users\98914\AppData\Local\Temp\tmprb1k1jouwandb\s8uhe7ga-diff.patch
Traceback (most recent call last):
  File "C:\Users\98914\anaconda3\envs\clonetop2_sccl\Lib\site-packages\wandb\apis\normalize.py", line 41, in wrapper
    return func(*args, **kwargs)
           ^^^^^^^^^^^^^^^^^^^^^
  File "C:\Users\98914\anaconda3\envs\clonetop2_sccl\Lib\site-packages\wandb\sdk\lib\retry.py", line 212, in wrapped_fn
    return retrier(*args, **kargs)
           ^^^^^^^^^^^^^^^^^^^^^^^
  File "C:\Users\98914\anaconda3\envs\clonetop2_sccl\Lib\site-packages\wandb\sdk\lib\retry.py", line 131, in __call__
    result = self._call_fn(*args, **kwargs)
             ^^^^^^^^^^^^^^^^^^^^^^^^^^^^^^
  File "C:\Users\98914\anaconda3\envs\clonetop2_sccl\Lib\site-packages\wandb\sdk\internal\internal_api.py", line 2313, in upload_file
    wandb._sentry.reraise(e)
  File "C:\Users\98914\anaconda3\envs\clonetop2_sccl\Lib\site-packages\wandb\analytics\sentry.py", line 146, in reraise
    raise exc.with_traceback(sys.exc_info()[2])
  File "C:\Users\98914\anaconda3\envs\clonetop2_sccl\Lib\site-packages\wandb\sdk\internal\internal_api.py", line 2285, in upload_file
    response.raise_for_status()
  File "C:\Users\98914\anaconda3\envs\clonetop2_sccl\Lib\site-packages\requests\models.py", line 1021, in raise_for_status
    raise HTTPError(http_error_msg, response=self)
requests.exceptions.HTTPError: 403 Client Error: Forbidden for url: https://storage.googleapis.com/wandb-production.appspot.com/mohammadvahidi-pro/sccl-2021/5pmk5w6i/diff.patch?Expires=1690947426&GoogleAccessId=gorilla-files-url-signer-man%40wandb-production.iam.gserviceaccount.com&Signature=Y7A69%2BYLQ2Q%2BI30O0wpglpWO7SzCjDd%2Bq65P1uA5GHMLG1JF4pIXY71K75gRVHmUXmxEyjkHSzvsEcBh8vrp6%2B78RjNpTqfYj5qR8WTRRGc1VGg3CJ3cIpgqVKTCnrHQKotl1wRKqetCbPgtwGTgZWd%2FpvqIJ6%2FvBgVtSZ%2BYNgzU1GTQqc%2BAVBhcqba181MNl10sVrKAMfLXO%2FhQM7%2FiNAeAoAiP4mm1EPF3efFqPwiPr7v7MiYB6Zz4s96NeR%2BeRgBNukWAJE0BjY20ES9XsasLH%2FYukulqVVzcKL7nhAWA3VEZ%2FJVPJoUUiNPdxL9DQQlhJwlTD7VtoCP3fdnKpQ%3D%3D

During handling of the above exception, another exception occurred:

Traceback (most recent call last):
  File "C:\Users\98914\anaconda3\envs\clonetop2_sccl\Lib\concurrent\futures\thread.py", line 58, in run
    result = self.fn(*self.args, **self.kwargs)
             ^^^^^^^^^^^^^^^^^^^^^^^^^^^^^^^^^^
  File "C:\Users\98914\anaconda3\envs\clonetop2_sccl\Lib\site-packages\wandb\filesync\step_upload.py", line 288, in run_and_notify
    self._do_upload_sync(event)
  File "C:\Users\98914\anaconda3\envs\clonetop2_sccl\Lib\site-packages\wandb\filesync\step_upload.py", line 330, in _do_upload_sync
    job.run()
  File "C:\Users\98914\anaconda3\envs\clonetop2_sccl\Lib\site-packages\wandb\filesync\upload_job.py", line 57, in run
    self.push()
  File "C:\Users\98914\anaconda3\envs\clonetop2_sccl\Lib\site-packages\wandb\filesync\upload_job.py", line 127, in push
    self._api.upload_file_retry(
  File "C:\Users\98914\anaconda3\envs\clonetop2_sccl\Lib\site-packages\wandb\apis\normalize.py", line 51, in wrapper
    raise CommError(message, error)
wandb.errors.CommError: <Response [403]>
2023-08-01 07:08:01,747 ERROR   gpu       :6552 [interfaces.py:monitor():144] Failed to sample metric: Not Supported
2023-08-01 07:08:01,748 ERROR   gpu       :6552 [interfaces.py:monitor():144] Failed to sample metric: Not Supported
2023-08-01 07:08:01,981 DEBUG   HandlerThread:6552 [handler.py:handle_request():144] handle_request: stop_status
2023-08-01 07:08:01,982 DEBUG   SenderThread:6552 [sender.py:send_request():396] send_request: stop_status
2023-08-01 07:08:03,468 DEBUG   SenderThread:6552 [sender.py:send():369] send: stats
2023-08-01 07:08:03,470 DEBUG   HandlerThread:6552 [handler.py:handle_request():144] handle_request: status_report
2023-08-01 07:08:03,840 ERROR   gpu       :6552 [interfaces.py:monitor():144] Failed to sample metric: Not Supported
2023-08-01 07:08:03,840 ERROR   gpu       :6552 [interfaces.py:monitor():144] Failed to sample metric: Not Supported
2023-08-01 07:08:05,933 ERROR   gpu       :6552 [interfaces.py:monitor():144] Failed to sample metric: Not Supported
2023-08-01 07:08:05,933 ERROR   gpu       :6552 [interfaces.py:monitor():144] Failed to sample metric: Not Supported
2023-08-01 07:08:08,119 ERROR   gpu       :6552 [interfaces.py:aggregate():161] Failed to serialize metric: division by zero
2023-08-01 07:08:08,121 ERROR   gpu       :6552 [interfaces.py:monitor():144] Failed to sample metric: Not Supported
2023-08-01 07:08:08,121 ERROR   gpu       :6552 [interfaces.py:monitor():144] Failed to sample metric: Not Supported
2023-08-01 07:08:08,527 DEBUG   HandlerThread:6552 [handler.py:handle_request():144] handle_request: status_report
2023-08-01 07:08:10,138 ERROR   gpu       :6552 [interfaces.py:monitor():144] Failed to sample metric: Not Supported
2023-08-01 07:08:10,139 ERROR   gpu       :6552 [interfaces.py:monitor():144] Failed to sample metric: Not Supported
2023-08-01 07:08:11,159 INFO    Thread-16 :6552 [dir_watcher.py:_on_file_modified():289] file/dir modified: D:\text_clustering_paper\my-forks\sccl_fork\wandb\run-20230801_070624-5pmk5w6i\files\upstream_diff_94cb2df46703d3266d43f731c56849ac84c15bc0.patch
2023-08-01 07:08:12,146 ERROR   gpu       :6552 [interfaces.py:monitor():144] Failed to sample metric: Not Supported
2023-08-01 07:08:12,146 ERROR   gpu       :6552 [interfaces.py:monitor():144] Failed to sample metric: Not Supported
2023-08-01 07:08:12,294 INFO    Thread-16 :6552 [dir_watcher.py:_on_file_modified():289] file/dir modified: D:\text_clustering_paper\my-forks\sccl_fork\wandb\run-20230801_070624-5pmk5w6i\files\upstream_diff_94cb2df46703d3266d43f731c56849ac84c15bc0.patch
2023-08-01 07:08:13,305 INFO    Thread-16 :6552 [dir_watcher.py:_on_file_modified():289] file/dir modified: D:\text_clustering_paper\my-forks\sccl_fork\wandb\run-20230801_070624-5pmk5w6i\files\upstream_diff_94cb2df46703d3266d43f731c56849ac84c15bc0.patch
2023-08-01 07:08:13,941 DEBUG   HandlerThread:6552 [handler.py:handle_request():144] handle_request: status_report
2023-08-01 07:08:14,337 ERROR   gpu       :6552 [interfaces.py:monitor():144] Failed to sample metric: Not Supported
2023-08-01 07:08:14,337 ERROR   gpu       :6552 [interfaces.py:monitor():144] Failed to sample metric: Not Supported
2023-08-01 07:08:15,588 INFO    Thread-16 :6552 [dir_watcher.py:_on_file_modified():289] file/dir modified: D:\text_clustering_paper\my-forks\sccl_fork\wandb\run-20230801_070624-5pmk5w6i\files\upstream_diff_94cb2df46703d3266d43f731c56849ac84c15bc0.patch
2023-08-01 07:08:16,351 ERROR   gpu       :6552 [interfaces.py:monitor():144] Failed to sample metric: Not Supported
2023-08-01 07:08:16,352 ERROR   gpu       :6552 [interfaces.py:monitor():144] Failed to sample metric: Not Supported
2023-08-01 07:08:16,625 INFO    Thread-16 :6552 [dir_watcher.py:_on_file_modified():289] file/dir modified: D:\text_clustering_paper\my-forks\sccl_fork\wandb\run-20230801_070624-5pmk5w6i\files\upstream_diff_94cb2df46703d3266d43f731c56849ac84c15bc0.patch
2023-08-01 07:08:17,645 INFO    Thread-16 :6552 [dir_watcher.py:_on_file_modified():289] file/dir modified: D:\text_clustering_paper\my-forks\sccl_fork\wandb\run-20230801_070624-5pmk5w6i\files\upstream_diff_94cb2df46703d3266d43f731c56849ac84c15bc0.patch
2023-08-01 07:08:18,355 ERROR   gpu       :6552 [interfaces.py:monitor():144] Failed to sample metric: Not Supported
2023-08-01 07:08:18,356 ERROR   gpu       :6552 [interfaces.py:monitor():144] Failed to sample metric: Not Supported
2023-08-01 07:08:19,025 DEBUG   HandlerThread:6552 [handler.py:handle_request():144] handle_request: status_report
2023-08-01 07:08:20,016 INFO    memory    :6552 [interfaces.py:monitor():140] Process proc.memory.rssMB has exited.
2023-08-01 07:08:20,017 ERROR   gpu       :6552 [interfaces.py:aggregate():161] Failed to serialize metric: division by zero
2023-08-01 07:08:20,018 DEBUG   SystemMonitor:6552 [system_monitor.py:_start():166] Finished system metrics aggregation loop
2023-08-01 07:08:20,018 DEBUG   SystemMonitor:6552 [system_monitor.py:_start():170] Publishing last batch of metrics
2023-08-01 07:08:20,022 DEBUG   SenderThread:6552 [sender.py:send():369] send: stats
2023-08-01 07:08:21,144 INFO    Thread-16 :6552 [dir_watcher.py:_on_file_modified():289] file/dir modified: D:\text_clustering_paper\my-forks\sccl_fork\wandb\run-20230801_070624-5pmk5w6i\files\upstream_diff_94cb2df46703d3266d43f731c56849ac84c15bc0.patch
2023-08-01 07:08:21,729 INFO    MainThread:6552 [internal.py:handle_exit():76] Internal process exited
2023-08-01 07:08:22,162 INFO    Thread-16 :6552 [dir_watcher.py:_on_file_modified():289] file/dir modified: D:\text_clustering_paper\my-forks\sccl_fork\wandb\run-20230801_070624-5pmk5w6i\files\upstream_diff_94cb2df46703d3266d43f731c56849ac84c15bc0.patch
